<?xml version="1.0"?>
<robot xmlns:xacro="http://www.ros.org/wiki/xacro">

  <xacro:include filename="$(find schunk_description)/urdf/lwa4p/lwa4p.gazebo.xacro" />
  <xacro:include filename="$(find schunk_description)/urdf/lwa4p/lwa4p.transmission.xacro" />
  
	<!-- arm reference positions -->
	<property name="arm_1_ref" value="0" />
	<property name="arm_2_ref" value="0" />
	<property name="arm_3_ref" value="0" />
	<property name="arm_4_ref" value="0" />
	<property name="arm_5_ref" value="0" />
	<property name="arm_6_ref" value="0" />
	<xacro:property name="joint_1_upper_limit" value="2.967059678" /> <!-- 170º -->
	<xacro:property name="joint_1_lower_limit" value="-2.967059678" /> <!-- -170º -->
	<xacro:property name="joint_2_upper_limit" value="1.919862144" /> <!-- 110º -->
	<xacro:property name="joint_2_lower_limit" value="-1.919862144" /> <!-- -110º -->
	<xacro:property name="joint_3_upper_limit" value="2.705260294" /> <!-- 155º -->
	<xacro:property name="joint_3_lower_limit" value="-2.705260294" /> <!-- -155º -->
	<xacro:property name="joint_4_upper_limit" value="2.967059678" /> <!-- 170º -->
	<xacro:property name="joint_4_lower_limit" value="-2.967059678" /> <!-- -170º -->
	<xacro:property name="joint_5_upper_limit" value="2.51327408" /> <!-- 140º -->
	<xacro:property name="joint_5_lower_limit" value="-2.51327408" /> <!-- -140º -->
	<xacro:property name="joint_6_upper_limit" value="2.967059678" /> <!-- 170º -->
	<xacro:property name="joint_6_lower_limit" value="-2.967059678" /> <!-- -170º -->
	<xacro:property name="joint_1_max_vel" value="1.25663706144" /> <!-- 72º/s -->
	<xacro:property name="joint_2_max_vel" value="1.25663706144" /> <!-- 72º/s -->
	<xacro:property name="joint_3_max_vel" value="1.25663706144" /> <!-- 72º/s -->
	<xacro:property name="joint_4_max_vel" value="1.25663706144" /> <!-- 72º/s -->	
	<xacro:property name="joint_5_max_vel" value="1.57079632679" /> <!-- 90º/s -->	
	<xacro:property name="joint_6_max_vel" value="1.57079632679" /> <!-- 90º/s -->
	
  <xacro:macro name="schunk_lwa4p" params="parent name *origin">

    <!-- joint between base_link and arm_0_link -->
    <joint name="${name}_0_joint" type="fixed" >
      <insert_block name="origin" />
      <parent link="${parent}" />
      <child link="${name}_0_link" />
    </joint>

    <link name="${name}_0_link">
		<inertial>
        <origin xyz="0 0 0" rpy="0 0 0" />
        <mass value="0.29364"/>
        <inertia ixx="0.01" ixy="0" ixz="0" iyy="0.01" iyz="0" izz="0.01" />
      </inertial>
       <visual>
        <origin xyz="0 0 0" rpy="0 0 0" />
        <geometry>
          <mesh filename="package://lwa4p_description/meshes/arm_0_link_v2.stl" />
        </geometry>
        <material name="Schunk/LightGrey" />
      </visual>
      
      <collision>
        <origin xyz="0 0 0" rpy="0 0 0" />
        <geometry>
          <mesh filename="package://lwa4p_description/meshes/arm_0_link_v2.stl" />
        </geometry>
      </collision>
    </link>

    <!-- joint between arm_0_link and arm_1_link -->
    <joint name="${name}_1_joint" type="revolute">
      <origin xyz="0 0 0.2051" rpy="0 0 0"/>
      <parent link="${name}_0_link"/>
      <child link="${name}_1_link"/>
      <axis xyz="0 0 1"/>
      <calibration rising="${arm_1_ref}"/>
      <dynamics damping="10" />
      <limit effort="370" velocity="${joint_1_max_vel}" lower="${joint_1_lower_limit}" upper="${joint_1_upper_limit}"/>
      <safety_controller k_position="20" k_velocity="50" soft_lower_limit="${-6.2831853 + 0.01}" soft_upper_limit="${6.2831853 - 0.01}" />
    </joint>

    <link name="${name}_1_link">
      <inertial>
        <origin xyz="0 0 0" rpy="0 0 0" />
        <mass value="0.29364"/>
        <inertia ixx="0.01" ixy="0" ixz="0" iyy="0.01" iyz="0" izz="0.01" />
      </inertial>
      
      <visual>
        <origin xyz="0 0 0" rpy="0 0 0" />
        <geometry>
          <mesh filename="package://lwa4p_description/meshes/arm_1_link.stl" />
        </geometry>
        <material name="Schunk/Blue" />
      </visual>
      
      <collision>
        <origin xyz="0 0 0" rpy="0 0 0" />
        <geometry>
          <mesh filename="package://lwa4p_description/meshes/arm_1_link.stl" />
        </geometry>
      </collision>
    </link>

    <!-- joint between arm_1_link and arm_2_link -->  
    <joint name="${name}_2_joint" type="revolute">
      <origin xyz="0 0 0" rpy="1.5708 0 0"/>
      <parent link="${name}_1_link"/>
      <child link="${name}_2_link"/>
      <axis xyz="0 0 1"/>
      <calibration rising="${arm_2_ref}"/>
      <dynamics damping="10" />
      <limit effort="370" velocity="${joint_2_max_vel}" lower="${joint_2_lower_limit}" upper="${joint_2_upper_limit}"/>
      <safety_controller k_position="20" k_velocity="50" soft_lower_limit="${-2.0943 + 0.01}" soft_upper_limit="${2.0943 - 0.01}" />
    </joint>

    <link name="${name}_2_link">
      <inertial>
        <origin xyz="0 0 0" rpy="0 0 0"/>
        <mass value="1.68311"/>
        <inertia ixx="0.03" ixy="0" ixz="0" iyy="0.03" iyz="0" izz="0.03" />
      </inertial>
      
      <visual>
        <origin xyz="0 0 0" rpy="0 0 0" />
        <geometry>
          <mesh filename="package://lwa4p_description/meshes/arm_2_link.stl" />
        </geometry>
        <material name="Schunk/LightGrey" />
      </visual>
      
      <collision>
        <origin xyz="0 0 0" rpy="0 0 0" />
        <geometry>
          <mesh filename="package://lwa4p_description/meshes/arm_2_link.stl" />
        </geometry>
      </collision>
    </link>

    <!-- joint between arm_2_link and arm_3_link -->  
    <joint name="${name}_3_joint" type="revolute">
      <origin xyz="0 0.350 0" rpy="0 3.14159 0"/>
      <parent link="${name}_2_link"/>
      <child link="${name}_3_link"/>
      <axis xyz="0 0 1"/>
      <calibration rising="${arm_3_ref}"/>
      <dynamics damping="5" />
      <limit effort="370" velocity="${joint_3_max_vel}" lower="${joint_3_lower_limit}" upper="${joint_3_upper_limit}"/>
      <safety_controller k_position="20" k_velocity="25" soft_lower_limit="${-6.2831853 + 0.01}" soft_upper_limit="${6.2831853 - 0.01}" />
    </joint>

    <link name="${name}_3_link">
      <inertial>
        <origin xyz="0 0 0" rpy="0 0 0"/>
        <mass value="2.1"/>
        <inertia ixx="0.03" ixy="0" ixz="0" iyy="0.03" iyz="0" izz="0.03" />
      </inertial>
      
      <visual>
        <origin xyz="0 0 0" rpy="0 0 0" />
        <geometry>
          <mesh filename="package://lwa4p_description/meshes/arm_3_link.stl" />
        </geometry>
        <material name="Schunk/Blue" />
      </visual>
      
      <collision>
        <origin xyz="0 0 0" rpy="0 0 0" />
        <geometry>
          <mesh filename="package://lwa4p_description/meshes/arm_3_link.stl" />
        </geometry>
      </collision>
    </link>  

    <!-- joint between arm_3_link and arm_4_link -->
    <joint name="${name}_4_joint" type="revolute">
      <origin xyz="0 0 0" rpy="-1.5708 3.14159 0" />
      <parent link="${name}_3_link"/>
      <child link="${name}_4_link"/>
      <axis xyz="0 0 1" />
      <calibration rising="${arm_4_ref}"/>
      <dynamics damping="5" />
      <limit effort="370" velocity="${joint_4_max_vel}" lower="${joint_4_lower_limit}" upper="${joint_4_upper_limit}"/>
      <safety_controller k_position="20" k_velocity="25" soft_lower_limit="${-2.0943951 + 0.01}" soft_upper_limit="${2.0943951 - 0.01}" />
    </joint>

    <link name="${name}_4_link">
      <inertial>
        <origin xyz="0 0 0" rpy="0 0 0"/>
        <mass value="1.68311"/>
        <inertia ixx="0.03" ixy="0" ixz="0" iyy="0.03" iyz="0" izz="0.03" />
      </inertial>
      
      <visual>
        <origin xyz="0 0 0" rpy="0 0 0" />
        <geometry>
          <mesh filename="package://lwa4p_description/meshes/arm_4_link.stl" />
        </geometry>
        <material name="Schunk/LightGrey" />
      </visual>
      
      <collision>
        <origin xyz="0 0 0" rpy="0 0 0" />
        <geometry>
          <mesh filename="package://lwa4p_description/meshes/arm_4_link.stl" />
        </geometry>
      </collision>
    </link>

    <!-- joint between arm_4_link and arm_5_link -->
    <joint name="${name}_5_joint" type="revolute">
      <origin xyz="0 0.005263 0.305" rpy="1.5708 0 3.14159" />
      <parent link="${name}_4_link"/>
      <child link="${name}_5_link"/>
      <axis xyz="0 0 1" />	
      <calibration rising="${arm_5_ref}"/>
      <dynamics damping="5" />
      <limit effort="370" velocity="${joint_5_max_vel}" lower="${joint_5_lower_limit}" upper="${joint_5_upper_limit}"/>
      <safety_controller k_position="20" k_velocity="25" soft_lower_limit="${-6.2831853 + 0.01}" soft_upper_limit="${6.2831853 - 0.01}" />
    </joint>

    <link name="${name}_5_link">
      <inertial>
        <origin xyz="0 0 0" rpy="0 0 0"/>
        <mass value="0.807"/>
        <inertia ixx="0.03" ixy="0" ixz="0" iyy="0.03" iyz="0" izz="0.03" />
      </inertial>
      
      <visual>
        <origin xyz="0 0 0" rpy="0 0 0" />
        <geometry>
          <mesh filename="package://lwa4p_description/meshes/arm_5_link.stl" />
        </geometry>
        <material name="Schunk/Blue" />
      </visual>
      
      <collision>
        <origin xyz="0 0 0" rpy="0 0 0" />
        <geometry>
          <mesh filename="package://lwa4p_description/meshes/arm_5_link.stl" />
        </geometry>
      </collision>
    </link>

    <!-- joint between arm_5_link and arm_6_link -->
    <joint name="${name}_6_joint" type="revolute">
      <origin xyz="0 0 0" rpy="-1.5708 0 0" />
      <parent link="${name}_5_link"/>
      <child link="${name}_6_link"/>
      <axis xyz="0 0 1" />
      <calibration rising="${arm_6_ref}"/>
      <dynamics damping="5" />
      <limit effort="370" velocity="${joint_6_max_vel}" lower="${joint_6_lower_limit}" upper="${joint_6_upper_limit}"/>
      <safety_controller k_position="20" k_velocity="25" soft_lower_limit="${-2.0943951 + 0.01}" soft_upper_limit="${2.0943951 - 0.01}" />
    </joint>

    <link name="${name}_6_link">
      <inertial>
        <origin xyz="0 0 0" rpy="0 0 0"/>
        <mass value="0.819"/>
        <inertia ixx="0.01" ixy="0" ixz="0" iyy="0.01" iyz="0" izz="0.01" />
      </inertial>
      
      <visual>
        <origin xyz="0 0 0" rpy="0 0 0" />
        <geometry>
          <mesh filename="package://lwa4p_description/meshes/arm_6_link.stl" />
        </geometry>
        <material name="Schunk/LightGrey" />
      </visual>
      
      <collision>
        <origin xyz="0 0 0" rpy="0 0 0" />
        <geometry>
          <mesh filename="package://lwa4p_description/meshes/arm_6_link.stl" />
        </geometry>
      </collision>
    </link>


    <!-- extensions -->
    <xacro:schunk_lwa4p_gazebo name="${name}" />
    <xacro:schunk_lwa4p_transmission name="${name}" />

  </xacro:macro>

</robot>
